<robot xmlns:xacro="http://wiki.ros.org/xacro">
	<xacro:macro name="ag95" params="joint_origin_offset joint_origin_angle hw_interface gripper_parent">

		<joint name="gripper_base_joint" type="fixed">
			<parent link="${gripper_parent}" />
			<child link="gripper_base_link" />
			<axis xyz="0 0 0" />
			<origin rpy="${joint_origin_angle}" xyz="${joint_origin_offset}" />
		</joint>
		<link name="gripper_base_link">
			<visual>
				<geometry>
					<mesh filename="package://cobot-description/meshes/ag95/gripper_base.STL" scale="0.001 0.001 0.001" />
				</geometry>
			</visual>
			<collision>
				<geometry>
					<mesh filename="package://cobot-description/meshes/ag95/gripper_base.STL" scale="0.001 0.001 0.001" />
				</geometry>
			</collision>
			<inertial>
				<mass value="0.83416" />
				<origin xyz="0.0 0.0 0.0" />
				<inertia ixx="0.0013016" ixy="-6.9374e-07" ixz="5.9848e-07" iyx="0.000000" iyy="0.00049972" iyz="2.0244E-07" izx="0.000000" izy="0.000000" izz="0.001498" />
			</inertial>
		</link>
		<gazebo reference="gripper_base_link">
			<implicitSpringDamper>
				1
			</implicitSpringDamper>
			<mu1>
				100000
			</mu1>
			<mu2>
				100000
			</mu2>
			<kp>
				100000000.0
			</kp>
			<kd>
				1.0
			</kd>
		</gazebo>
		<joint name="gripper_finger1_joint" type="revolute">
			<parent link="gripper_base_link" />
			<child link="gripper_finger1_knuckle_link" />
			<axis xyz="0 -1 0" />
			<origin rpy="0.0 0.0 3.14159265359" xyz="-0.016 0 0.10586" />
			<limit effort="1000" lower="0.0" upper="0.65" velocity="2.0" />
		</joint>
		<joint name="gripper_finger2_joint" type="revolute">
			<parent link="gripper_base_link" />
			<child link="gripper_finger2_knuckle_link" />
			<axis xyz="0 -1 0" />
			<origin rpy="0.0 0.0 0.0" xyz="0.0160 0 0.10586" />
			<limit effort="1000" lower="-3.14" upper="3.14" velocity="100.0" />
			<mimic joint="gripper_finger1_joint" />
		</joint>
		<link name="gripper_finger1_knuckle_link">
			<visual>
				<geometry>
					<mesh filename="package://cobot-description/meshes/ag95/crank_Link.STL" scale="0.001 0.001 0.001" />
				</geometry>
			</visual>
			<collision>
				<geometry>
					<mesh filename="package://cobot-description/meshes/ag95/crank_Link.STL" scale="0.001 0.001 0.001" />
				</geometry>
			</collision>
			<inertial>
				<mass value="0.011111" />
				<origin xyz="0.0 0.0 0.0" />
				<inertia ixx="3.88172e-06" ixy="-2.29456e-13" ixz="8.33e-07" iyx="0.000000" iyy="1.92174e-06" iyz="2.04435e-13" izx="0.000000" izy="0.000000" izz="4.32374e-06" />
			</inertial>
		</link>
		<gazebo reference="gripper_finger1_knuckle_link">
			<implicitSpringDamper>
				1
			</implicitSpringDamper>
			<mu1>
				100000
			</mu1>
			<mu2>
				100000
			</mu2>
			<kp>
				100000000.0
			</kp>
			<kd>
				1.0
			</kd>
		</gazebo>
		<link name="gripper_finger2_knuckle_link">
			<visual>
				<geometry>
					<mesh filename="package://cobot-description/meshes/ag95/crank_Link.STL" scale="0.001 0.001 0.001" />
				</geometry>
			</visual>
			<collision>
				<geometry>
					<mesh filename="package://cobot-description/meshes/ag95/crank_Link.STL" scale="0.001 0.001 0.001" />
				</geometry>
			</collision>
			<inertial>
				<mass value="0.011111" />
				<origin xyz="0.0 0.0 0.0" />
				<inertia ixx="3.88172e-06" ixy="-2.29456e-13" ixz="8.33e-07" iyx="0.000000" iyy="1.92174e-06" iyz="2.04435e-13" izx="0.000000" izy="0.000000" izz="4.32374e-06" />
			</inertial>
		</link>
		<gazebo reference="gripper_finger2_knuckle_link">
			<implicitSpringDamper>
				1
			</implicitSpringDamper>
			<mu1>
				100000
			</mu1>
			<mu2>
				100000
			</mu2>
			<kp>
				100000000.0
			</kp>
			<kd>
				1.0
			</kd>
		</gazebo>
		<joint name="gripper_finger1_finger_joint" type="continuous">
			<parent link="gripper_finger1_knuckle_link" />
			<child link="gripper_finger1_finger_link" />
			<axis xyz="0 -1 0" />
			<origin rpy="0 0 0" xyz="0.0292080077784 0.0 -0.0227132622407" />
			<limit effort="0.1" lower="-3.14" upper="3.14" velocity="100.0" />
			<mimic joint="gripper_finger1_joint" multiplier="0.4563942" offset="0" />
		</joint>
		<joint name="gripper_finger2_finger_joint" type="continuous">
			<parent link="gripper_finger2_knuckle_link" />
			<child link="gripper_finger2_finger_link" />
			<axis xyz="0 -1 0" />
			<origin rpy="0 0 0" xyz="0.0292080077784 0.0 -0.0227132622407" />
			<limit effort="0.1" lower="-3.14" upper="3.14" velocity="100.0" />
			<mimic joint="gripper_finger1_joint" multiplier="0.4563942" offset="0" />
		</joint>
		<link name="gripper_finger1_finger_link">
			<visual>
				<geometry>
					<mesh filename="package://cobot-description/meshes/ag95/rod_Link.STL" scale="0.001 0.001 0.001" />
				</geometry>
			</visual>
			<collision>
				<geometry>
					<mesh filename="package://cobot-description/meshes/ag95/rod_Link.STL" scale="0.001 0.001 0.001" />
				</geometry>
			</collision>
			<inertial>
				<mass value="0.0222871" />
				<origin xyz="0.0 0.0 0.0" />
				<inertia ixx="8.72836e-06" ixy="7.0843e-15" ixz="-2.18833e-06" iyx="-0.000002" iyy="7.26157e-06" iyz="7.6579e-15" izx="0.000000" izy="0.000000" izz="3.3425e-06" />
			</inertial>
		</link>
		<gazebo reference="gripper_finger1_finger_link">
			<implicitSpringDamper>
				1
			</implicitSpringDamper>
			<mu1>
				100000
			</mu1>
			<mu2>
				100000
			</mu2>
			<kp>
				100000000.0
			</kp>
			<kd>
				1.0
			</kd>
		</gazebo>
		<link name="gripper_finger2_finger_link">
			<visual>
				<geometry>
					<mesh filename="package://cobot-description/meshes/ag95/rod_Link.STL" scale="0.001 0.001 0.001" />
				</geometry>
			</visual>
			<collision>
				<geometry>
					<mesh filename="package://cobot-description/meshes/ag95/rod_Link.STL" scale="0.001 0.001 0.001" />
				</geometry>
			</collision>
			<inertial>
				<mass value="0.0222871" />
				<origin xyz="0.0 0.0 0.0" />
				<inertia ixx="8.72836e-06" ixy="7.0843e-15" ixz="-2.18833e-06" iyx="-0.000002" iyy="7.26157e-06" iyz="7.6579e-15" izx="0.000000" izy="0.000000" izz="3.3425e-06" />
			</inertial>
		</link>
		<gazebo reference="gripper_finger2_finger_link">
			<implicitSpringDamper>
				1
			</implicitSpringDamper>
			<mu1>
				100000
			</mu1>
			<mu2>
				100000
			</mu2>
			<kp>
				100000000.0
			</kp>
			<kd>
				1.0
			</kd>
		</gazebo>
		<joint name="gripper_finger1_inner_knuckle_joint" type="continuous">
			<parent link="gripper_base_link" />
			<child link="gripper_finger1_inner_knuckle_link" />
			<axis xyz="0 -1 0" />
			<origin rpy="0.0 0.0 3.14159265359" xyz="-0.016 0 0.10586" />
			<limit effort="0.1" lower="-3.14" upper="3.14" velocity="100.0" />
			<mimic joint="gripper_finger1_joint" multiplier="1.49462955" offset="0" />
		</joint>
		<joint name="gripper_finger2_inner_knuckle_joint" type="continuous">
			<parent link="gripper_base_link" />
			<child link="gripper_finger2_inner_knuckle_link" />
			<axis xyz="0 -1 0" />
			<origin rpy="0.0 0.0 0.0" xyz="0.016 0 0.10586" />
			<limit effort="0.1" lower="-3.14" upper="3.14" velocity="100.0" />
			<mimic joint="gripper_finger1_joint" multiplier="1.49462955" offset="0" />
		</joint>
		<link name="gripper_finger1_inner_knuckle_link">
			<visual>
				<geometry>
					<mesh filename="package://cobot-description/meshes/ag95/proximal_phalanx_Link.STL" scale="0.001 0.001 0.001" />
				</geometry>
			</visual>
			<collision>
				<geometry>
					<mesh filename="package://cobot-description/meshes/ag95/proximal_phalanx_Link.STL" scale="0.001 0.001 0.001" />
				</geometry>
			</collision>
			<inertial>
				<mass value="0.0318004" />
				<origin xyz="0.0 0.0 0.0" />
				<inertia ixx="1.39848e-05" ixy="-9.54763e-15" ixz="-5.01422e-06" iyx="0.000000" iyy="1.04943e-05" iyz="8.94585e-16" izx="0.000000" izy="0.000000" izz="1.36183e-05" />
			</inertial>
		</link>
		<gazebo reference="gripper_finger1_inner_knuckle_link">
			<implicitSpringDamper>
				1
			</implicitSpringDamper>
			<mu1>
				100000
			</mu1>
			<mu2>
				100000
			</mu2>
			<kp>
				100000000.0
			</kp>
			<kd>
				1.0
			</kd>
		</gazebo>
		<link name="gripper_finger2_inner_knuckle_link">
			<visual>
				<geometry>
					<mesh filename="package://cobot-description/meshes/ag95/proximal_phalanx_Link.STL" scale="0.001 0.001 0.001" />
				</geometry>
			</visual>
			<collision>
				<geometry>
					<mesh filename="package://cobot-description/meshes/ag95/proximal_phalanx_Link.STL" scale="0.001 0.001 0.001" />
				</geometry>
			</collision>
			<inertial>
				<mass value="0.0318004" />
				<origin xyz="0.0 0.0 0.0" />
				<inertia ixx="1.39848e-05" ixy="-9.54763e-15" ixz="-5.01422e-06" iyx="0.000000" iyy="1.04943e-05" iyz="8.94585e-16" izx="0.000000" izy="0.000000" izz="1.36183e-05" />
			</inertial>
		</link>
		<gazebo reference="gripper_finger2_inner_knuckle_link">
			<implicitSpringDamper>
				1
			</implicitSpringDamper>
			<mu1>
				100000
			</mu1>
			<mu2>
				100000
			</mu2>
			<kp>
				100000000.0
			</kp>
			<kd>
				1.0
			</kd>
		</gazebo>
		<joint name="gripper_finger1_finger_tip_joint" type="continuous">
			<parent link="gripper_finger1_inner_knuckle_link" />
			<child link="gripper_finger1_finger_tip_link" />
			<axis xyz="0 1 0" />
			<origin rpy="0.0 0.0 0.0" xyz="0.0394969463769 0.0 0.0382752038125 " />
			<limit effort="0.1" lower="-3.14" upper="3.14" velocity="100.0" />
			<mimic joint="gripper_finger1_joint" multiplier="1.49462955" />
		</joint>
		<joint name="gripper_finger2_finger_tip_joint" type="continuous">
			<parent link="gripper_finger2_inner_knuckle_link" />
			<child link="gripper_finger2_finger_tip_link" />
			<axis xyz="0 1 0" />
			<origin rpy="0.0 0.0 0.0" xyz="0.0394969463769  0.0 0.0382752038125" />
			<limit effort="0.1" lower="-3.14" upper="3.14" velocity="100.0" />
			<mimic joint="gripper_finger1_joint" multiplier="1.49462955" />
		</joint>
		<link name="gripper_finger1_finger_tip_link">
			<visual>
				<geometry>
					<mesh filename="package://cobot-description/meshes/ag95/distal_phalanx_Link.STL" scale="0.001 0.001 0.001" />
				</geometry>
			</visual>
			<collision>
				<geometry>
					<mesh filename="package://cobot-description/meshes/ag95/distal_phalanx_Link.STL" scale="0.001 0.001 0.001" />
				</geometry>
			</collision>
			<inertial>
				<mass value="0.0124305" />
				<origin xyz="0.0 0.0 0.0" />
				<inertia ixx="2.84217e-06" ixy="-2.48048e-15" ixz="8.24539e-07" iyx="0.000000" iyy="3.03961e-06" iyz="2.16427e-13" izx="0.000000" izy="0.000000" izz="1.11815e-06" />
			</inertial>
		</link>
		<gazebo reference="gripper_finger1_finger_tip_link">
			<implicitSpringDamper>
				1
			</implicitSpringDamper>
			<mu1>
				100000
			</mu1>
			<mu2>
				100000
			</mu2>
			<kp>
				100000000.0
			</kp>
			<kd>
				1.0
			</kd>
		</gazebo>
		<link name="gripper_finger2_finger_tip_link">
			<visual>
				<geometry>
					<mesh filename="package://cobot-description/meshes/ag95/distal_phalanx_Link.STL" scale="0.001 0.001 0.001" />
				</geometry>
			</visual>
			<collision>
				<geometry>
					<mesh filename="package://cobot-description/meshes/ag95/distal_phalanx_Link.STL" scale="0.001 0.001 0.001" />
				</geometry>
			</collision>
			<inertial>
				<mass value="0.0124305" />
				<origin xyz="0.0 0.0 0.0" />
				<inertia ixx="2.84217e-06" ixy="-2.48048e-15" ixz="8.24539e-07" iyx="0.000000" iyy="3.03961e-06" iyz="2.16427e-13" izx="0.000000" izy="0.000000" izz="1.11815e-06" />
			</inertial>
		</link>
		<gazebo reference="gripper_finger2_finger_tip_link">
			<implicitSpringDamper>
				1
			</implicitSpringDamper>
			<mu1>
				100000
			</mu1>
			<mu2>
				100000
			</mu2>
			<kp>
				100000000.0
			</kp>
			<kd>
				1.0
			</kd>
		</gazebo>

		<xacro:include filename="$(find cobot-description)/urdf/ag95/ag95.transmission.xacro" />
		<xacro:ag95_transmission hw_interface="${hw_interface}" />

	</xacro:macro>
</robot>